Workbook
Name VisibleFunds: 'PPT Attributes'!#REF!

Sheet Selector Sheet 
B2: Risk Profile | C2: =D5 -> Conservative
B3: Enter Portfolio Size: | C3: 500000000
A5: Asset Class | D5: Conservative | E5: Please select the Risk Profile of the Client from drop down in Cell D5 or create a coustom portfolio by entering values in D6 to D9 | H5: POLICY GUIDELINES:
A6: Equity | D6: =VLOOKUP('Selector Sheet '!D5,'Drop Downs'!$B$25:$F$29,3,FALSE) -> 0.4 | H6: 1. Min allocation of fresh inflows towards MP funds = 75% of gross inflows 2. Max deviation of fresh inflows towards Whitelisted funds = 20% of gross inflows 3. Max deviation of fresh inflows towards funds other than Model Portfolio/Whitelisted funds recommended by a client = 5% of gross inflows 4. Max Exposure allowed towards a Whitelist Scheme = 5% of gross inflows 5. Max Exposure towards a particular AMC = 25% of overall portfolio 6. Max Exposure towards a scheme =10% of overall portfolio
A7: Hybrid | D7: =VLOOKUP('Selector Sheet '!D5,'Drop Downs'!$B$25:$F$29,4,FALSE) -> 0.2
A8: Alternate | D8: =VLOOKUP('Selector Sheet '!D5,'Drop Downs'!$B$25:$F$29,5,FALSE) -> 0.1
A9: Debt | D9: =VLOOKUP('Selector Sheet '!D5,'Drop Downs'!$B$25:$F$29,2,FALSE) -> 0.3
A10: Total | D10: =SUM(D6:D9) -> 1
A12: Model Portfolio
A13: Equity | C13: 1 | D13: =$C$13*$D$6 -> 0.4 | E13: Amount | F13: Allocation across the products can be changed manually per client requirement
A14: Large Cap | C14: 1 | D14: =C14*$D$6 -> 0.4 | E14: =IF(D14*$C$3=0,"",D14*$C$3) -> 200000000 | H14: Core funds
A15: FALSE | B15: Renaissance Opportunities Fund PMS | C15: =IF(A15=FALSE,0,$C$14/COUNTIF($A$15:$A$19,TRUE)) -> 0 | D15: =C15*$D$6 -> 0 | E15: =IF(D15*$C$3=0,"",D15*$C$3) | H15: Whitelist funds
A16: TRUE | B16: Nippon India Large Cap Fund(G) | C16: =IF(A16=FALSE,0,$C$14/COUNTIF($A$15:$A$19,TRUE)) -> 0.5 | D16: =C16*$D$6 -> 0.2 | E16: =IF(D16*$C$3=0,"",D16*$C$3) -> 100000000 | H16: Watchlist - No Fresh allocations to be made
A17: FALSE | B17: ICICI Pru Bluechip Fund(G) | C17: =IF(A17=FALSE,0,$C$14/COUNTIF($A$15:$A$19,TRUE)) -> 0 | D17: =C17*$D$6 -> 0 | E17: =IF(D17*$C$3=0,"",D17*$C$3)
A18: FALSE | B18: Kotak Bluechip Fund(G) | C18: =IF(A18=FALSE,0,$C$14/COUNTIF($A$15:$A$19,TRUE)) -> 0 | D18: =$D$6*C18 -> 0 | E18: =IF(D18*$C$3=0,"",D18*$C$3)
A19: TRUE | B19: Canara Rob Bluechip Equity Fund-Reg(G) | C19: =IF(A19=FALSE,0,$C$14/COUNTIF($A$15:$A$19,TRUE)) -> 0.5 | D19: =$D$6*C19 -> 0.2 | E19: =IF(D19*$C$3=0,"",D19*$C$3) -> 100000000
A20: Large -Mid Cap | C20: =VLOOKUP($D$5,'Drop Downs'!$I$3:$M$7,3,FALSE) -> 0.2 | D20: =C20*$D$6 -> 0.08 | E20: =IF(D20*$C$3=0,"",D20*$C$3) -> 40000000
A21: TRUE | B21: SBI Large & Midcap Fund-Reg(G) | C21: =IF(A21=FALSE,0,$C$20/COUNTIF($A$21:$A$23,TRUE)) -> 0.1 | D21: =C21*$D$6 -> 0.04 | E21: =IF(D21*$C$3=0,"",D21*$C$3) -> 20000000
A22: FALSE | B22: ICICI Pru Large & Mid Cap Fund(G) | C22: =IF(A22=FALSE,0,$C$20/COUNTIF($A$21:$A$23,TRUE)) -> 0 | D22: =C22*$D$6 -> 0 | E22: =IF(D22*$C$3=0,"",D22*$C$3)
A23: TRUE | B23: Canara Rob Emerg Equities Fund-Reg(G) | C23: =IF(A23=FALSE,0,$C$20/COUNTIF($A$21:$A$23,TRUE)) -> 0.1 | D23: =C23*$D$6 -> 0.04 | E23: =IF(D23*$C$3=0,"",D23*$C$3) -> 20000000
A24: Mid/Small cap | C24: =VLOOKUP($D$5,'Drop Downs'!$I$3:$M$7,5,FALSE) -> 0 | D24: =C24*$D$6 -> 0 | E24: =IF(D24*$C$3=0,"",D24*$C$3)
A25: FALSE | B25: Abakkus Emerging Oppurtunities PMS | C25: =IF(A25=FALSE,0,$C$24/COUNTIF($A$25:$A$26,TRUE)) -> 0 | D25: =$D$6*C25 -> 0 | E25: =IF(D25*$C$3=0,"",D25*$C$3)
A26: FALSE | B26: AAA Budding Beast | C26: =IF(A26=FALSE,0,$C$24/COUNTIF($A$25:$A$26,TRUE)) -> 0 | D26: =$D$6*C26 -> 0 | E26: =IF(D26*$C$3=0,"",D26*$C$3)
A27: Multicap | C27: =VLOOKUP($D$5,'Drop Downs'!$I$3:$M$7,4,FALSE) -> 0.5 | D27: =C27*$D$6 -> 0.2 | E27: =IF(D27*$C$3=0,"",D27*$C$3) -> 100000000
A28: FALSE | B28: AAA IOP PMS / AIF | C28: =IF(A28=FALSE,0,$C$27/COUNTIF($A$28:$A$36,TRUE)) -> 0 | D28: =C28*$D$6 -> 0 | E28: =IF(D28*$C$3=0,"",D28*$C$3)
A29: FALSE | B29: Nippon India Multi Cap Fund(G) | C29: =IF(A29=FALSE,0,$C$27/COUNTIF($A$28:$A$36,TRUE)) -> 0 | D29: =$D$6*C29 -> 0 | E29: =IF(D29*$C$3=0,"",D29*$C$3)
A30: FALSE | B30: SBI Contra Fund-Reg(G) | C30: =IF(A30=FALSE,0,$C$27/COUNTIF($A$28:$A$36,TRUE)) -> 0 | D30: =C30*$D$6 -> 0 | E30: =IF(D30*$C$3=0,"",D30*$C$3)
A31: FALSE | B31: Abakkus All Cap PMS | C31: =IF(A31=FALSE,0,$C$27/COUNTIF($A$28:$A$36,TRUE)) -> 0 | D31: =$D$6*C31 -> 0 | E31: =IF(D31*$C$3=0,"",D31*$C$3)
A32: FALSE | B32: Renaissance India Next Portfolio | C32: =IF(A32=FALSE,0,$C$27/COUNTIF($A$28:$A$36,TRUE)) -> 0 | D32: =C32*$D$6 -> 0 | E32: =IF(D32*$C$3=0,"",D32*$C$3)
A33: FALSE | B33: Parag Parikh Flexi Cap Fund-Reg(G) | C33: =IF(A33=FALSE,0,$C$27/COUNTIF($A$28:$A$36,TRUE)) -> 0 | D33: =C33*$D$6 -> 0 | E33: =IF(D33*$C$3=0,"",D33*$C$3)
A34: FALSE | B34: Bouyant Oppurtunites PMS | C34: =IF(A34=FALSE,0,$C$27/COUNTIF($A$28:$A$36,TRUE)) -> 0 | D34: =C34*$D$6 -> 0 | E34: =IF(D34*$C$3=0,"",D34*$C$3)
A35: FALSE | B35: UTI Flexi Cap Fund-Reg(G) | C35: =IF(A35=FALSE,0,$C$27/COUNTIF($A$28:$A$36,TRUE)) -> 0 | D35: =$D$6*C35 -> 0 | E35: =IF(D35*$C$3=0,"",D35*$C$3)
A36: FALSE | B36: ASK IEP PMS / AIF | C36: =IF(A36=FALSE,0,$C$27/COUNTIF($A$28:$A$36,TRUE)) -> 0 | D36: =$D$6*C36 -> 0 | E36: =IF(D36*$C$3=0,"",D36*$C$3)
A37: Total Equity | C37: =SUM($C$28:$C$36)+C26+SUM($C$21:$C$23)+SUM($C$15:$C$19) -> 1.2 | D37: =SUM($D$28:$D$36)+$D$26+SUM($D$21:$D$23)+SUM($D$15:$D$19) -> 0.48 | E37: =IF(D37*$C$3=0,"",D37*$C$3) -> 240000000
A38: Hybrid | C38: 1 | D38: =C38*$D$7 -> 0.2 | E38: =IF(D38*$C$3=0,"",D38*$C$3) -> 100000000
A39: FALSE | B39: ICICI Pru Balanced Advantage Fund(G) | C39: =IF(A39=FALSE,0,$C$38/COUNTIF($A$39:$A$42,TRUE)) -> 0 | D39: =$D$7*C39 -> 0 | E39: =IF(D39*$C$3=0,"",D39*$C$3)
A40: FALSE | B40: Tata Balanced Adv Fund-Reg(G) | C40: =IF(A40=FALSE,0,$C$38/COUNTIF($A$39:$A$42,TRUE)) -> 0 | D40: =$D$7*C40 -> 0 | E40: =IF(D40*$C$3=0,"",D40*$C$3)
A41: FALSE | B41: Kotak Balanced Advantage Fund-Reg(G) | C41: =IF(A41=FALSE,0,$C$38/COUNTIF($A$39:$A$42,TRUE)) -> 0 | D41: =$D$7*C41 -> 0 | E41: =IF(D41*$C$3=0,"",D41*$C$3)
A42: FALSE | B42: Edelweiss Balanced Advantage Fund-Reg(G) | C42: =IF(A42=FALSE,0,$C$38/COUNTIF($A$39:$A$42,TRUE)) -> 0 | D42: =$D$7*C42 -> 0 | E42: =IF(D42*$C$3=0,"",D42*$C$3)
A43: Total Hybrid | C43: =SUM($C$39:$C$42) -> 0 | D43: =SUM(D39:D42) -> 0 | E43: =IF(D43*$C$3=0,"",D43*$C$3)
...

Sheet Output Dashboard (option 1)
A1: Portfolio
A3: Selected Funds | B3: Allocation | C3: Large | D3: Mid | E3: Small | S3: Stock Exposure | V3: Position Concentration | Z3: Equity Sector Exposure | AD3: Fund | AF3: Returns | AQ3: Year | AR3: Equity | AS3: =IF($AR$3='Drop Downs'!$I$18,'Drop Downs'!$D$2,'Drop Downs'!$E$2) -> Nifty 50
A4: {=_xlfn._xlws.FILTER('Selector Sheet '!$B$14:$B$43,'Selector Sheet '!$A$14:$A$43=TRUE,"No funds selected")} -> Nippon India Large Cap Fund(G) | B4: {=_xlfn.IFNA(VLOOKUP($A$4:$A$25,'Selector Sheet '!$B$14:$D$43,3,FALSE),"")} -> 0.2 | C4: {=VLOOKUP(_xlfn.ANCHORARRAY($A$4),Source_Data!$T$2:$W$24,2,FALSE)} -> 0.837409 | D4: {=VLOOKUP(_xlfn.ANCHORARRAY($A$4),Source_Data!$T$2:$W$24,3,FALSE)} -> 0.107269 | E4: {=VLOOKUP(_xlfn.ANCHORARRAY($A$4),Source_Data!$T$2:$W$24,4,FALSE)} -> 0.038736 | S4: Name | T4: Percentage | V4: Top 3 | W4: =SUM($T$5:$T$7) -> #N/A | Z4: {=_xlfn._xlws.SORT(_xlfn.HSTACK(_xlfn.UNIQUE(Source_Data!$J$2:$J$192),_xlfn.BYROW(_xlfn.UNIQUE(Source_Data!$J$2:$J$192),_xlfn.LAMBDA(_xlpm.x,SUMIF(Source_Data!$J$2:$J$192,_xlpm.x,Source_Data!$L$2:$L$192)))),2,-1)} -> Financial | AA4: #N/A | AE4: Expense Ratio | AF4: 1 month | AG4: 3 months | AH4: 6 months | AI4: {=IFERROR(INDEX('Performance Data'!#REF!,MATCH(TRIM(_xlfn.ANCHORARRAY($AD$5)),'Performance Data'!#REF!,0),MATCH(TRIM(#REF!),'Performance Data'!#REF!,0)),"")} -> #VALUE! | AJ4: 1 Year | AK4: 2 Year | AL4: 3 Year | AM4: 5 Year | AN4: 10 Year | AQ4: CY 2025 | AR4: {=SUMPRODUCT(_xlfn._xlws.FILTER((VLOOKUP(_xlfn._xlws.FILTER('Drop Downs'!$J$26:$J$48,'Drop Downs'!$I$26:$I$48=$L$30,"Not Found"),$AD$33:$AN$48,2,FALSE)),NOT(ISNA((VLOOKUP(_xlfn._xlws.FILTER('Drop Downs'!$J$26:$J$48,'Drop Downs'!$I$26:$I$48=$L$30,"Not Found"),$AD$33:$AN$48,2,FALSE))))),_xlfn.IFNA(VLOOKUP(_xlfn._xlws.FILTER(_xlfn.ANCHORARRAY($AD$33),ISNUMBER(MATCH(_xlfn.ANCHORARRAY($AD$33),_xlfn._xlws.FILTER('Drop Downs'!$J$26:$J$48,'Drop Downs'!$I$26:$I$48=$L$30,"Not Found"),0))),'Selector Sheet '!$B$14:$D$43,2,FALSE),0))} -> 0.0478129 | AS4: {=IF($AS$3='Drop Downs'!$D$2,(VLOOKUP('Output Dashboard (option 1)'!$AQ$4:$AQ$11,'Drop Downs'!$C$3:$E$10,2,FALSE)),VLOOKUP('Output Dashboard (option 1)'!$AQ$4:$AQ$11,'Drop Downs'!$C$3:$E$10,3,FALSE))} -> -0.005306
A5: Canara Rob Bluechip Equity Fund-Reg(G) | B5: 0.2 | C5: 0.904036 | D5: 0.053861 | E5: 0 | S5: {=_xlfn._xlws.SORT(_xlfn.TAKE(_xlfn._xlws.SORT(_xlfn.HSTACK(_xlfn.UNIQUE(Source_Data!$B$2:$B$567),_xlfn.BYROW(_xlfn.UNIQUE(Source_Data!$B$2:$B$567),_xlfn.LAMBDA(_xlpm.x,SUMIF(Source_Data!$B$2:$B$567,_xlpm.x,Source_Data!$D$2:$D$567)))),2,-1),20),2,-1)} -> HDFC Bank | T5: #N/A | V5: Top5 | W5: =SUM($T$5:$T$9) -> #N/A | Z5: Technology | AA5: #N/A | AD5: {=IF($A$4:$A$19>0,$A$4:$A$19,"")} -> Nippon India Large Cap Fund(G) | AE5: {=IFERROR(INDEX('Performance Data'!$B$3:$AN$293,MATCH(TRIM(_xlfn.ANCHORARRAY($AD$5)),'Performance Data'!$B$3:$B$294,0),MATCH(TRIM(AE$4),'Performance Data'!$B$4:$AM$4,0)),"")} -> 1.51 | AF5: {=IFERROR(INDEX('Performance Data'!$B$3:$AN$293,MATCH(TRIM(_xlfn.ANCHORARRAY($AD$5)),'Performance Data'!$B$3:$B$294,0),MATCH(TRIM(AF$4),'Performance Data'!$B$4:$AM$4,0)),"")} -> -0.017875 | AG5: {=IFERROR(INDEX('Performance Data'!$B$3:$AN$293,MATCH(TRIM(_xlfn.ANCHORARRAY($AD$5)),'Performance Data'!$B$3:$B$294,0),MATCH(TRIM(AG$4),'Performance Data'!$B$4:$AM$4,0)),"")} -> 0.047609 | AH5: {=IFERROR(INDEX('Performance Data'!$B$3:$AN$293,MATCH(TRIM(_xlfn.ANCHORARRAY($AD$5)),'Performance Data'!$B$3:$B$294,0),MATCH(TRIM(AH$4),'Performance Data'!$B$4:$AM$4,0)),"")} -> 0.078495 | AI5: {=IFERROR(INDEX('Performance Data'!$B$3:$AN$293,MATCH(TRIM(_xlfn.ANCHORARRAY($AD$5)),'Performance Data'!$B$3:$B$294,0),MATCH(TRIM(AI$4),'Performance Data'!$B$4:$AM$4,0)),"")} | AJ5: {=IFERROR(INDEX('Performance Data'!$B$3:$AN$293,MATCH(TRIM(_xlfn.ANCHORARRAY($AD$5)),'Performance Data'!$B$3:$B$294,0),MATCH(TRIM(AJ$4),'Performance Data'!$B$4:$AM$4,0)),"")} -> 0.006832 | AK5: {=IFERROR(INDEX('Performance Data'!$B$3:$AN$293,MATCH(TRIM(_xlfn.ANCHORARRAY($AD$5)),'Performance Data'!$B$3:$B$294,0),MATCH(TRIM(AK$4),'Performance Data'!$B$4:$AM$4,0)),"")} | AL5: {=IFERROR(INDEX('Performance Data'!$B$3:$AN$293,MATCH(TRIM(_xlfn.ANCHORARRAY($AD$5)),'Performance Data'!$B$3:$B$294,0),MATCH(TRIM(AL$4),'Performance Data'!$B$4:$AM$4,0)),"")} -> 0.204123 | ... AN5: {=IFERROR(INDEX('Performance Data'!$B$3:$AN$293,MATCH(TRIM(_xlfn.ANCHORARRAY($AD$5)),'Performance Data'!$B$3:$B$294,0),MATCH(TRIM(AN$4),'Performance Data'!$B$4:$AM$4,0)),"")} -> 0.137065 | AQ5: 2024 | AR5: {=SUMPRODUCT(_xlfn._xlws.FILTER((VLOOKUP(_xlfn._xlws.FILTER('Drop Downs'!$J$26:$J$48,'Drop Downs'!$I$26:$I$48=$AR$3,"Not Found"),$AD$33:$AN$48,3,FALSE)),NOT(ISNA((VLOOKUP(_xlfn._xlws.FILTER('Drop Downs'!$J$26:$J$48,'Drop Downs'!$I$26:$I$48=$AR$3,"Not Found"),$AD$33:$AN$48,3,FALSE))))),_xlfn.IFNA(VLOOKUP(_xlfn._xlws.FILTER(_xlfn.ANCHORARRAY($AD$33),ISNUMBER(MATCH(_xlfn.ANCHORARRAY($AD$33),_xlfn._xlws.FILTER('Drop Downs'!$J$26:$J$48,'Drop Downs'!$I$26:$I$48=$AR$3,"Not Found"),0))),'Selector Sheet '!$B$14:$D$43,2,FALSE),0))} -> 0.22449831 | AS5: 0.08804769
A6: SBI Large & Midcap Fund-Reg(G) | B6: 0.04 | C6: 0.433817 | D6: 0.360591 | E6: 0.149174 | S6: ICICI Bank | T6: #N/A | V6: Top 10 | W6: =SUM($T$5:$T$14) -> #N/A | Z6: Consumer Discretionary | AA6: #N/A | AD6: Canara Rob Bluechip Equity Fund-Reg(G) | AE6: 1.64 | AF6: -0.022278 | AG6: 0.029528 | AH6: 0.065354 | AJ6: 0.018666 | AL6: 0.161045 | AM6: 0.186387 | AN6: 0.131291 | AQ6: 2023 | AR6: {=SUMPRODUCT(_xlfn._xlws.FILTER((VLOOKUP(_xlfn._xlws.FILTER('Drop Downs'!$J$26:$J$41,'Drop Downs'!$I$26:$I$41=$AR$3,"Not Found"),$AD$33:$AN$48,4,FALSE)),NOT(ISNA((VLOOKUP(_xlfn._xlws.FILTER('Drop Downs'!$J$26:$J$41,'Drop Downs'!$I$26:$I$41=$AR$3,"Not Found"),$AD$33:$AN$48,4,FALSE))))),_xlfn.IFNA(VLOOKUP(_xlfn._xlws.FILTER(_xlfn.ANCHORARRAY($AD$33),ISNUMBER(MATCH(_xlfn.ANCHORARRAY($AD$33),_xlfn._xlws.FILTER('Drop Downs'!$J$26:$J$41,'Drop Downs'!$I$26:$I$41=$AR$3,"Not Found"),0))),'Selector Sheet '!$B$14:$D$43,2,FALSE),0))} -> 0.3226543 | AS6: 0.20027839
A7: Canara Rob Emerg Equities Fund-Reg(G) | B7: 0.04 | C7: 0.453308 | D7: 0.392334 | E7: 0.125245 | S7: Reliance Ind | T7: #N/A | V7: Top 20 | W7: =SUM($T$5:$T$24) -> #N/A | Z7: Energy & Utilities | AA7: #N/A | AD7: SBI Large & Midcap Fund-Reg(G) | AE7: 1.58 | AF7: -0.009427 | AG7: 0.065682 | AH7: 0.085126 | AJ7: 0.02127 | AL7: 0.192237 | AM7: 0.246868 | AN7: 0.141788 | AQ7: 2022 | AR7: {=SUMPRODUCT(_xlfn._xlws.FILTER((VLOOKUP(_xlfn._xlws.FILTER('Drop Downs'!$J$26:$J$41,'Drop Downs'!$I$26:$I$41=$AR$3,"Not Found"),$AD$33:$AN$48,5,FALSE)),NOT(ISNA((VLOOKUP(_xlfn._xlws.FILTER('Drop Downs'!$J$26:$J$41,'Drop Downs'!$I$26:$I$41=$AR$3,"Not Found"),$AD$33:$AN$48,5,FALSE))))),_xlfn.IFNA(VLOOKUP(_xlfn._xlws.FILTER(_xlfn.ANCHORARRAY($AD$33),ISNUMBER(MATCH(_xlfn.ANCHORARRAY($AD$33),_xlfn._xlws.FILTER('Drop Downs'!$J$26:$J$41,'Drop Downs'!$I$26:$I$41=$AR$3,"Not Found"),0))),'Selector Sheet '!$B$14:$D$43,2,FALSE),0))} -> 0.066347195 | AS7: 0.043289607
S8: Infosys | T8: #N/A | Z8: Consumer Staples | AA8: #N/A | AD8: Canara Rob Emerg Equities Fund-Reg(G) | AE8: 1.6 | AF8: -0.025189 | AG8: 0.055282 | AH8: 0.073313 | AJ8: 0.005758 | AL8: 0.173117 | AM8: 0.221895 | AN8: 0.147989 | AQ8: 2021 | AR8: {=SUMPRODUCT(_xlfn._xlws.FILTER((VLOOKUP(_xlfn._xlws.FILTER('Drop Downs'!$J$26:$J$41,'Drop Downs'!$I$26:$I$41=$AR$3,"Not Found"),$AD$33:$AN$48,7,FALSE)),NOT(ISNA((VLOOKUP(_xlfn._xlws.FILTER('Drop Downs'!$J$26:$J$41,'Drop Downs'!$I$26:$I$41=$AR$3,"Not Found"),$AD$33:$AN$48,7,FALSE))))),_xlfn.IFNA(VLOOKUP(_xlfn._xlws.FILTER(_xlfn.ANCHORARRAY($AD$33),ISNUMBER(MATCH(_xlfn.ANCHORARRAY($AD$33),_xlfn._xlws.FILTER('Drop Downs'!$J$26:$J$41,'Drop Downs'!$I$26:$I$41=$AR$3,"Not Found"),0))),'Selector Sheet '!$B$14:$D$43,2,FALSE),0))} -> 0.36089185 | AS8: 0.24119298
S9: Larsen & Toubro | T9: #N/A | Z9: Industrials | AA9: #N/A | AQ9: 2020 | AR9: {=SUMPRODUCT(_xlfn._xlws.FILTER((VLOOKUP(_xlfn._xlws.FILTER('Drop Downs'!$J$26:$J$41,'Drop Downs'!$I$26:$I$41=$AR$3,"Not Found"),$AD$33:$AN$48,9,FALSE)),NOT(ISNA((VLOOKUP(_xlfn._xlws.FILTER('Drop Downs'!$J$26:$J$41,'Drop Downs'!$I$26:$I$41=$AR$3,"Not Found"),$AD$33:$AN$48,9,FALSE))))),_xlfn.IFNA(VLOOKUP(_xlfn._xlws.FILTER(_xlfn.ANCHORARRAY($AD$33),ISNUMBER(MATCH(_xlfn.ANCHORARRAY($AD$33),_xlfn._xlws.FILTER('Drop Downs'!$J$26:$J$41,'Drop Downs'!$I$26:$I$41=$AR$3,"Not Found"),0))),'Selector Sheet '!$B$14:$D$43,2,FALSE),0))} -> 0.18012754 | AS9: 0.14901651
S10: Bharti Airtel | T10: #N/A | Z10: Materials | AA10: #N/A | AQ10: 2019 | AR10: {=SUMPRODUCT(_xlfn._xlws.FILTER((VLOOKUP(_xlfn._xlws.FILTER('Drop Downs'!$J$26:$J$41,'Drop Downs'!$I$26:$I$41=$AR$3,"Not Found"),$AD$33:$AN$48,10,FALSE)),NOT(ISNA((VLOOKUP(_xlfn._xlws.FILTER('Drop Downs'!$J$26:$J$41,'Drop Downs'!$I$26:$I$41=$AR$3,"Not Found"),$AD$33:$AN$48,10,FALSE))))),_xlfn.IFNA(VLOOKUP(_xlfn._xlws.FILTER(_xlfn.ANCHORARRAY($AD$33),ISNUMBER(MATCH(_xlfn.ANCHORARRAY($AD$33),_xlfn._xlws.FILTER('Drop Downs'!$J$26:$J$41,'Drop Downs'!$I$26:$I$41=$AR$3,"Not Found"),0))),'Selector Sheet '!$B$14:$D$43,2,FALSE),0))} -> 0.13016268 | AS10: 0.12022039
S11: Mahindra & Mahindra | T11: #N/A | Z11: Healthcare | AA11: #N/A | AQ11: 2018 | AR11: {=SUMPRODUCT(_xlfn._xlws.FILTER((VLOOKUP(_xlfn._xlws.FILTER('Drop Downs'!$J$26:$J$41,'Drop Downs'!$I$26:$I$41=$AR$3,"Not Found"),$AD$33:$AN$48,11,FALSE)),NOT(ISNA((VLOOKUP(_xlfn._xlws.FILTER('Drop Downs'!$J$26:$J$41,'Drop Downs'!$I$26:$I$41=$AR$3,"Not Found"),$AD$33:$AN$48,11,FALSE))))),_xlfn.IFNA(VLOOKUP(_xlfn._xlws.FILTER(_xlfn.ANCHORARRAY($AD$33),ISNUMBER(MATCH(_xlfn.ANCHORARRAY($AD$33),_xlfn._xlws.FILTER('Drop Downs'!$J$26:$J$41,'Drop Downs'!$I$26:$I$41=$AR$3,"Not Found"),0))),'Selector Sheet '!$B$14:$D$43,2,FALSE),0))} -> 0.0014160416 | AS11: 0.031512625
S12: Axis Bank | T12: #N/A | Z12: Real Estate | AA12: #N/A
S13: ITC | T13: #N/A | Z13: Diversified | AA13: #N/A
S14: SBI | T14: #N/A | Z14: Cash (Unclassified) | AA14: 0
S15: Maruti Suzuki | T15: #N/A
S16: NTPC | T16: #N/A
S17: Tata Consultancy | T17: #N/A
S18: Sun Pharmaceutical | T18: #N/A
S19: Ultratech Cement | T19: #N/A
S20: Interglobe Aviation | T20: #N/A
S21: Hindustan Unilever | T21: #N/A | V21: Market Cap Exposure | W21: Portfolio | X21: Equity
S22: Bajaj Finance | T22: #N/A | V22: Large | W22: {=SUMPRODUCT(Source_Data!$U$2:$U$24,_xlfn.IFNA(VLOOKUP(Source_Data!$T$2:$T$24,'Selector Sheet '!$B$15:$D$43,3,FALSE),0))} -> 0.383774 | X22: =($W$22/SUM($W$22:$W$24))*1 -> 0.8256028
S23: Kotak Bank | T23: #N/A | V23: Mid | W23: {=SUMPRODUCT(Source_Data!$V$2:$V$24,_xlfn.IFNA(VLOOKUP(Source_Data!$T$2:$T$24,'Selector Sheet '!$B$15:$D$43,3,FALSE),0))} -> 0.062343 | X23: =($W$23/SUM($W$22:$W$24))*1 -> 0.13411684
S24: Tech Mahindra | T24: #N/A | V24: Small | W24: {=SUMPRODUCT(Source_Data!$W$2:$W$24,_xlfn.IFNA(VLOOKUP(Source_Data!$T$2:$T$24,'Selector Sheet '!$B$15:$D$43,3,FALSE),0))} -> 0.01872396 | X24: =($W$24/SUM($W$22:$W$24))*1 -> 0.040280357
A28: Returns Summary | K28: Backtested Retruns
A30: Fund | C30: Returns | K30: Year | L30: Equity | M30: =IF($L$30='Drop Downs'!$I$18,'Drop Downs'!$D$2,'Drop Downs'!$E$2) -> Nifty 50
B31: Expense Ratio | C31: 1 month | D31: 3 months | E31: 6 months | F31: 1 Year | G31: 3 Year | H31: 5 Year | I31: 10 Year | K31: CY 2025 | L31: {=_xlfn.LET(_xlpm.FilteredList,_xlfn._xlws.FILTER('Drop Downs'!$J$26:$J$48,'Drop Downs'!$I$26:$I$48=$L$30),_xlpm.DataValues,_xlfn.IFNA(VLOOKUP(_xlpm.FilteredList,$A$57:$I$78,2,FALSE),0),_xlpm.Weights,_xlfn.IFNA(VLOOKUP(_xlpm.FilteredList,'Selector Sheet '!$B$14:$D$43,2,FALSE),0),SUMPRODUCT(_xlpm.DataValues,_xlpm.Weights))} -> 0.0478129 | M31: {=IF($M$30='Drop Downs'!$D$2,(VLOOKUP('Output Dashboard (option 1)'!$AQ$4:$AQ$11,'Drop Downs'!$C$3:$E$10,2,FALSE)),VLOOKUP('Output Dashboard (option 1)'!$AQ$4:$AQ$11,'Drop Downs'!$C$3:$E$10,3,FALSE))} -> -0.005306 | AD31: Fund | AF31: Returns
A32: {=IF($A$4:$A$25>0,$A$4:$A$25,"")} -> Nippon India Large Cap Fund(G) | B32: {=IFERROR(INDEX('Performance Data'!$B$3:$AN$293,MATCH(TRIM(_xlfn.ANCHORARRAY($A$32)),'Performance Data'!$B$3:$B$294,0),MATCH(TRIM(B$31),'Performance Data'!$B$4:$AM$4,0)),"")} -> 1.51 | C32: {=IFERROR(INDEX('Performance Data'!$B$3:$AN$293,MATCH(TRIM(_xlfn.ANCHORARRAY($A$32)),'Performance Data'!$B$3:$B$294,0),MATCH(TRIM(C$31),'Performance Data'!$B$4:$AM$4,0)),"")} -> -0.017875 | D32: {=IFERROR(INDEX('Performance Data'!$B$3:$AN$293,MATCH(TRIM(_xlfn.ANCHORARRAY($A$32)),'Performance Data'!$B$3:$B$294,0),MATCH(TRIM(D$31),'Performance Data'!$B$4:$AM$4,0)),"")} -> 0.047609 | E32: {=IFERROR(INDEX('Performance Data'!$B$3:$AN$293,MATCH(TRIM(_xlfn.ANCHORARRAY($A$32)),'Performance Data'!$B$3:$B$294,0),MATCH(TRIM(E$31),'Performance Data'!$B$4:$AM$4,0)),"")} -> 0.078495 | F32: {=IFERROR(INDEX('Performance Data'!$B$3:$AN$293,MATCH(TRIM(_xlfn.ANCHORARRAY($A$32)),'Performance Data'!$B$3:$B$294,0),MATCH(TRIM(F$31),'Performance Data'!$B$4:$AM$4,0)),"")} -> 0.006832 | G32: {=IFERROR(INDEX('Performance Data'!$B$3:$AN$293,MATCH(TRIM(_xlfn.ANCHORARRAY($A$32)),'Performance Data'!$B$3:$B$294,0),MATCH(TRIM(G$31),'Performance Data'!$B$4:$AM$4,0)),"")} -> 0.204123 | H32: {=IFERROR(INDEX('Performance Data'!$B$3:$AN$293,MATCH(TRIM(_xlfn.ANCHORARRAY($A$32)),'Performance Data'!$B$3:$B$294,0),MATCH(TRIM(H$31),'Performance Data'!$B$4:$AM$4,0)),"")} -> 0.251486 | I32: {=IFERROR(INDEX('Performance Data'!$B$3:$AN$293,MATCH(TRIM(_xlfn.ANCHORARRAY($A$32)),'Performance Data'!$B$3:$B$294,0),MATCH(TRIM(I$31),'Performance Data'!$B$4:$AM$4,0)),"")} -> 0.137065 | K32: 2024 | L32: {=_xlfn.LET(_xlpm.FilteredList,_xlfn._xlws.FILTER('Drop Downs'!$J$26:$J$48,'Drop Downs'!$I$26:$I$48=$L$30),_xlpm.DataValues,_xlfn.IFNA(VLOOKUP(_xlpm.FilteredList,$A$57:$I$78,3,FALSE),0),_xlpm.Weights,_xlfn.IFNA(VLOOKUP(_xlpm.FilteredList,'Selector Sheet '!$B$14:$D$43,2,FALSE),0),SUMPRODUCT(_xlpm.DataValues,_xlpm.Weights))} -> 0.22449831 | M32: 0.08804769 | AE32: CY 2025 | AF32: 2024 | AG32: 2023 | AH32: 2022 | AI32: 2021 | AJ32: 2021 | AK32: 2019 | AL32: 2020 | AM32: 2019 | AN32: 2018
A33: Canara Rob Bluechip Equity Fund-Reg(G) | B33: 1.64 | C33: -0.022278 | D33: 0.029528 | E33: 0.065354 | F33: 0.018666 | G33: 0.161045 | H33: 0.186387 | I33: 0.131291 | K33: 2023 | L33: {=_xlfn.LET(_xlpm.FilteredList,_xlfn._xlws.FILTER('Drop Downs'!$J$26:$J$48,'Drop Downs'!$I$26:$I$48=$L$30),_xlpm.DataValues,_xlfn.IFNA(VLOOKUP(_xlpm.FilteredList,$A$57:$I$78,4,FALSE),0),_xlpm.Weights,_xlfn.IFNA(VLOOKUP(_xlpm.FilteredList,'Selector Sheet '!$B$14:$D$43,2,FALSE),0),SUMPRODUCT(_xlpm.DataValues,_xlpm.Weights))} -> 0.3226543 | M33: 0.20027839 | AD33: {=IF($A$4:$A$19>0,$A$4:$A$19,"")} -> Nippon India Large Cap Fund(G) | AE33: {=_xlfn.IFNA(INDEX('Performance Data'!$B$4:$AN$294,MATCH(_xlfn.ANCHORARRAY($AD$33),'Performance Data'!$B$4:$B$294,0),MATCH(AE$32,'Performance Data'!$B$4:$AM$4,0)),"")} -> 0.045961 | AF33: {=_xlfn.IFNA(INDEX('Performance Data'!$B$4:$AN$294,MATCH(_xlfn.ANCHORARRAY($AD$33),'Performance Data'!$B$4:$B$294,0),MATCH(AF$32,'Performance Data'!$B$4:$AM$4,0)),"")} -> 0.18239725 | AG33: {=_xlfn.IFNA(INDEX('Performance Data'!$B$4:$AN$294,MATCH(_xlfn.ANCHORARRAY($AD$33),'Performance Data'!$B$4:$B$294,0),MATCH(AG$32,'Performance Data'!$B$4:$AM$4,0)),"")} -> 0.32147843 | AH33: {=_xlfn.IFNA(INDEX('Performance Data'!$B$4:$AN$294,MATCH(_xlfn.ANCHORARRAY($AD$33),'Performance Data'!$B$4:$B$294,0),MATCH(AH$32,'Performance Data'!$B$4:$AM$4,0)),"")} -> 0.11327834 | AI33: {=_xlfn.IFNA(INDEX('Performance Data'!$B$4:$AN$294,MATCH(_xlfn.ANCHORARRAY($AD$33),'Performance Data'!$B$4:$B$294,0),MATCH(AI$32,'Performance Data'!$B$4:$AM$4,0)),"")} -> 0.32367195 | AJ33: {=_xlfn.IFNA(INDEX('Performance Data'!$B$4:$AN$294,MATCH(_xlfn.ANCHORARRAY($AD$33),'Performance Data'!$B$4:$B$294,0),MATCH(AJ$32,'Performance Data'!$B$4:$AM$4,0)),"")} -> 0.32367195 | AK33: {=_xlfn.IFNA(INDEX('Performance Data'!$B$4:$AN$294,MATCH(_xlfn.ANCHORARRAY($AD$33),'Performance Data'!$B$4:$B$294,0),MATCH(AK$32,'Performance Data'!$B$4:$AM$4,0)),"")} -> 0.072519095 | AL33: {=_xlfn.IFNA(INDEX('Performance Data'!$B$4:$AN$294,MATCH(_xlfn.ANCHORARRAY($AD$33),'Performance Data'!$B$4:$B$294,0),MATCH(AL$32,'Performance Data'!$B$4:$AM$4,0)),"")} -> 0.049081268 | ... AN33: {=_xlfn.IFNA(INDEX('Performance Data'!$B$4:$AN$294,MATCH(_xlfn.ANCHORARRAY($AD$33),'Performance Data'!$B$4:$B$294,0),MATCH(AN$32,'Performance Data'!$B$4:$AM$4,0)),"")} -> -0.0020039659
A34: SBI Large & Midcap Fund-Reg(G) | B34: 1.58 | C34: -0.009427 | D34: 0.065682 | E34: 0.085126 | F34: 0.02127 | G34: 0.192237 | H34: 0.246868 | I34: 0.141788 | K34: 2022 | L34: {=_xlfn.LET(_xlpm.FilteredList,_xlfn._xlws.FILTER('Drop Downs'!$J$26:$J$48,'Drop Downs'!$I$26:$I$48=$L$30),_xlpm.DataValues,_xlfn.IFNA(VLOOKUP(_xlpm.FilteredList,$A$57:$I$78,5,FALSE),0),_xlpm.Weights,_xlfn.IFNA(VLOOKUP(_xlpm.FilteredList,'Selector Sheet '!$B$14:$D$43,2,FALSE),0),SUMPRODUCT(_xlpm.DataValues,_xlpm.Weights))} -> 0.066347195 | M34: 0.043289607 | AD34: Canara Rob Bluechip Equity Fund-Reg(G) | AE34: 0.039245 | AF34: 0.1778818 | AG34: 0.22216925 | AH34: 0.0081711127 | AI34: 0.2454355 | AJ34: 0.2454355 | AK34: 0.15679591 | AL34: 0.2305709 | AM34: 0.15679591 | AN34: 0.033920705
A35: Canara Rob Emerg Equities Fund-Reg(G) | B35: 1.6 | C35: -0.025189 | D35: 0.055282 | E35: 0.073313 | F35: 0.005758 | G35: 0.173117 | H35: 0.221895 | I35: 0.147989 | K35: 2021 | L35: {=_xlfn.LET(_xlpm.FilteredList,_xlfn._xlws.FILTER('Drop Downs'!$J$26:$J$48,'Drop Downs'!$I$26:$I$48=$L$30),_xlpm.DataValues,_xlfn.IFNA(VLOOKUP(_xlpm.FilteredList,$A$57:$I$78,6,FALSE),0),_xlpm.Weights,_xlfn.IFNA(VLOOKUP(_xlpm.FilteredList,'Selector Sheet '!$B$14:$D$43,2,FALSE),0),SUMPRODUCT(_xlpm.DataValues,_xlpm.Weights))} -> 0.36089185 | M35: 0.24119298 | AD35: SBI Large & Midcap Fund-Reg(G) | AE35: 0.049623 | AF35: 0.18042995 | AG35: 0.26792765 | AH35: 0.072700548 | AI35: 0.39345344 | AJ35: 0.39345344 | AK35: 0.068227156 | AL35: 0.15756187 | AM35: 0.068227156 | AN35: -0.052504277
K36: 2020 | L36: {=_xlfn.LET(_xlpm.FilteredList,_xlfn._xlws.FILTER('Drop Downs'!$J$26:$J$48,'Drop Downs'!$I$26:$I$48=$L$30),_xlpm.DataValues,_xlfn.IFNA(VLOOKUP(_xlpm.FilteredList,$A$57:$I$78,7,FALSE),0),_xlpm.Weights,_xlfn.IFNA(VLOOKUP(_xlpm.FilteredList,'Selector Sheet '!$B$14:$D$43,2,FALSE),0),SUMPRODUCT(_xlpm.DataValues,_xlpm.Weights))} -> 0.18012754 | M36: 0.14901651 | AD36: Canara Rob Emerg Equities Fund-Reg(G) | AE36: 0.002476 | AF36: 0.26315789 | AG36: 0.24037692 | AH36: -0.016475862 | AI36: 0.36992781 | AJ36: 0.36992781 | AK36: 0.086824666 | AL36: 0.24545267 | AM36: 0.086824666 | AN36: -0.092919002
K37: 2019 | L37: {=_xlfn.LET(_xlpm.FilteredList,_xlfn._xlws.FILTER('Drop Downs'!$J$26:$J$48,'Drop Downs'!$I$26:$I$48=$L$30),_xlpm.DataValues,_xlfn.IFNA(VLOOKUP(_xlpm.FilteredList,$A$57:$I$78,8,FALSE),0),_xlpm.Weights,_xlfn.IFNA(VLOOKUP(_xlpm.FilteredList,'Selector Sheet '!$B$14:$D$43,2,FALSE),0),SUMPRODUCT(_xlpm.DataValues,_xlpm.Weights))} -> 0.13016268 | M37: 0.12022039
K38: 2018 | L38: {=_xlfn.LET(_xlpm.FilteredList,_xlfn._xlws.FILTER('Drop Downs'!$J$26:$J$48,'Drop Downs'!$I$26:$I$48=$L$30),_xlpm.DataValues,_xlfn.IFNA(VLOOKUP(_xlpm.FilteredList,$A$57:$I$78,9,FALSE),0),_xlpm.Weights,_xlfn.IFNA(VLOOKUP(_xlpm.FilteredList,'Selector Sheet '!$B$14:$D$43,2,FALSE),0),SUMPRODUCT(_xlpm.DataValues,_xlpm.Weights))} -> 0.0014160416 | M38: 0.031512625
A55: Fund | B55: Returns
B56: CY 2025 | C56: 2024 | D56: 2023 | E56: 2022 | F56: 2021 | G56: 2020 | H56: 2019 | I56: 2018
A57: {=IF($A$4:$A$25>0,$A$4:$A$25,"")} -> Nippon India Large Cap Fund(G) | B57: {=_xlfn.IFNA(INDEX('Performance Data'!$B$4:$AN$294,MATCH(_xlfn.ANCHORARRAY($A$57),'Performance Data'!$B$4:$B$294,0),MATCH(B$56,'Performance Data'!$B$4:$AM$4,0)),"")} -> 0.045961 | C57: {=_xlfn.IFNA(INDEX('Performance Data'!$B$4:$AN$294,MATCH(_xlfn.ANCHORARRAY($A$57),'Performance Data'!$B$4:$B$294,0),MATCH(C$56,'Performance Data'!$B$4:$AM$4,0)),"")} -> 0.18239725 | D57: {=_xlfn.IFNA(INDEX('Performance Data'!$B$4:$AN$294,MATCH(_xlfn.ANCHORARRAY($A$57),'Performance Data'!$B$4:$B$294,0),MATCH(D$56,'Performance Data'!$B$4:$AM$4,0)),"")} -> 0.32147843 | E57: {=_xlfn.IFNA(INDEX('Performance Data'!$B$4:$AN$294,MATCH(_xlfn.ANCHORARRAY($A$57),'Performance Data'!$B$4:$B$294,0),MATCH(E$56,'Performance Data'!$B$4:$AM$4,0)),"")} -> 0.11327834 | F57: {=_xlfn.IFNA(INDEX('Performance Data'!$B$4:$AN$294,MATCH(_xlfn.ANCHORARRAY($A$57),'Performance Data'!$B$4:$B$294,0),MATCH(F$56,'Performance Data'!$B$4:$AM$4,0)),"")} -> 0.32367195 | G57: {=_xlfn.IFNA(INDEX('Performance Data'!$B$4:$AN$294,MATCH(_xlfn.ANCHORARRAY($A$57),'Performance Data'!$B$4:$B$294,0),MATCH(G$56,'Performance Data'!$B$4:$AM$4,0)),"")} -> 0.049081268 | H57: {=_xlfn.IFNA(INDEX('Performance Data'!$B$4:$AN$294,MATCH(_xlfn.ANCHORARRAY($A$57),'Performance Data'!$B$4:$B$294,0),MATCH(H$56,'Performance Data'!$B$4:$AM$4,0)),"")} -> 0.072519095 | I57: {=_xlfn.IFNA(INDEX('Performance Data'!$B$4:$AN$294,MATCH(_xlfn.ANCHORARRAY($A$57),'Performance Data'!$B$4:$B$294,0),MATCH(I$56,'Performance Data'!$B$4:$AM$4,0)),"")} -> -0.0020039659
A58: Canara Rob Bluechip Equity Fund-Reg(G) | B58: 0.039245 | C58: 0.1778818 | D58: 0.22216925 | E58: 0.0081711127 | F58: 0.2454355 | G58: 0.2305709 | H58: 0.15679591 | I58: 0.033920705
A59: SBI Large & Midcap Fund-Reg(G) | B59: 0.049623 | C59: 0.18042995 | D59: 0.26792765 | E59: 0.072700548 | F59: 0.39345344 | G59: 0.15756187 | H59: 0.068227156 | I59: -0.052504277
A60: Canara Rob Emerg Equities Fund-Reg(G) | B60: 0.002476 | C60: 0.26315789 | D60: 0.24037692 | E60: -0.016475862 | F60: 0.36992781 | G60: 0.24545267 | H60: 0.086824666 | I60: -0.092919002
A84: Portfolio Details | L84: Market Cap Allocation
...

Sheet Performance Data
B2: As on 31st March'2025
B3: Large-Cap Funds | C3: Expense Ratio | D3: Corpus | F3: Returns | N3: CY Year Returns | AS3: Banking and PSU Fund | AT3: Expense Ratio | AU3: Corpus | AX3: Risk Return | BF3: Yearly Performance
B4: Large-Cap Funds | C4: Expense Ratio | D4: Month End | E4: AUM (Cr.) | F4: 1 month | G4: 3 months | H4: 6 months | I4: 1 Year | J4: 3 Year | K4: 5 Year | L4: 10 Year | N4: CY 2025 | O4: 2024 | P4: 2023 | Q4: 2022 | R4: 2021 | S4: 2020 | T4: 2019 | U4: 2018 | V4: 2017 | W4: 2016 | X4: 2015 | Y4: 2014 | Z4: 2013 | AA4: 2012 | AB4: 2011 | AC4: 2010 | AD4: 2009 | AE4: 2008 | AF4: 2007 | AG4: 2006 | AH4: 2005 | AI4: 2004 | AJ4: 2003 | AK4: 2002 | AL4: 2001 | AM4: 2000 | AN4: Sharpe Ratio | AO4: Beta | AP4: PE | AQ4: PB | AT4: Ratio | AU4: Month End | AV4: AUM (Cr.) | AX4: 1 Month | AY4: 3 Months | AZ4: 6 Months | BA4: 1 Year | BB4: 3 Years | BC4: 5 Years | BD4: 10 Years | BF4: 2025 | BG4: 2024 | BH4: 2023 | BI4: 2022 | BJ4: 2021 | BK4: 2020 | BL4: 2019 | BM4: 2018 | BN4: 2017 | BO4: 2016 | BP4: 2015 | BQ4: 2014 | BR4: 2013 | BS4: 2012 | BT4: 2011 | BU4: 2010
B5: Aditya Birla SL Frontline Equity Fund(G) | C5: 1.63 | D5: 45838 | E5: 30927.442 | F5: -0.022096 | G5: 0.0339 | H5: 0.074165 | I5: 0.002579 | J5: 0.162269 | K5: 0.200447 | L5: 0.120113 | N5: 0.048146 | O5: 0.15565864 | P5: 0.23070806 | Q5: 0.03537611 | R5: 0.27904615 | S5: 0.14220046 | T5: 0.076442841 | U5: -0.029051233 | V5: 0.3057575 | W5: 0.074258361 | X5: 0.011016302 | Y5: 0.44723989 | Z5: 0.092529199 | AA5: 0.36073435 | AB5: -0.22925026 | AC5: 0.18701429 | AD5: 0.90451182 | AE5: -0.48500123 | AF5: 0.62258129 | AG5: 0.47701827 | AH5: 0.41771094 | AI5: 0.21461187 | AJ5: 0.90803485 | AK5: 0.033 | AL5: NA | AM5: NA | AS5: Altacura AI Absolute Return Fund LLP | AX5: -0.0135 | AY5: 0.0086208814 | AZ5: 0.03917979 | BA5: 0.10592712 | BB5: 0.14255572 | BC5: NA | BD5: NA | BF5: 0.020220022 | BG5: 0.14136615 | BH5: 0.15236217 | BI5: 0.14957355 | BJ5: 0.02509849 | BK5: NA | BL5: NA | BM5: NA | BN5: NA | BO5: NA | BP5: NA | BQ5: NA | BR5: NA | BS5: NA
B6: Axis Bluechip Fund-Reg(G) | C6: 1.56 | D6: 45838 | E6: 34373.875 | F6: -0.02403 | G6: 0.02089 | H6: 0.054932 | I6: 0.001833 | J6: 0.116325 | K6: 0.147279 | L6: 0.116562 | N6: 0.030516 | O6: 0.13725872 | P6: 0.1744905 | Q6: -0.056599698 | R6: 0.20641126 | S6: 0.19719189 | T6: 0.18571957 | U6: 0.065431612 | V6: 0.38030468 | W6: -0.036182486 | X6: -0.012428793 | Y6: 0.40846098 | Z6: 0.13493377 | AA6: 0.31733915 | AB6: -0.22550676 | AC6: 0.184 | AD6: NA | AE6: NA | AF6: NA | AG6: NA | AH6: NA | AI6: NA | AJ6: NA | AK6: NA | AL6: NA | AM6: NA | AS6: ASK Absolute Return Fund | AX6: 0.0063 | AY6: 0.018304052 | AZ6: 0.05671931 | BA6: 0.13126329 | BB6: NA | BC6: NA | BD6: NA | BF6: 0.023497403 | BG6: 0.18006666 | BH6: NA | BI6: NA | BJ6: NA | BK6: NA | BL6: NA | BM6: NA | BN6: NA | BO6: NA | BP6: NA | BQ6: NA | BR6: NA | BS6: NA
B7: Bandhan Large Cap Fund-Reg(G) | C7: 2.03 | D7: 45838 | E7: 1928.3758 | F7: -0.009759 | G7: 0.045971 | H7: 0.085497 | I7: 0.015454 | J7: 0.165152 | K7: 0.184913 | L7: 0.12064 | N7: 0.03456 | O7: 0.18704035 | P7: 0.26771925 | Q7: -0.023183528 | R7: 0.26750314 | S7: 0.17413082 | T7: 0.10589769 | U7: -0.042266355 | V7: 0.34163436 | W7: 0.05284827 | X7: -0.056727651 | Y7: 0.30393294 | Z7: 0.080174756 | AA7: 0.27433523 | AB7: -0.23337071 | AC7: 0.18519573 | AD7: 0.74044045 | AE7: -0.51274325 | AF7: 0.48198398 | AG7: 0.1734 | AH7: NA | AI7: NA | AJ7: NA | AK7: NA | AL7: NA | AM7: NA | AS7: White Space Alpha Fund 2 | AX7: 0.0292 | AY7: 0.031531756 | AZ7: -0.0041260413 | BA7: 0.10107678 | BB7: 0.18686587 | BC7: 0.30179096 | BF7: 0.012964184 | BG7: 0.16109792 | BH7: 0.31611864 | BI7: 0.09406489 | BJ7: 0.44720911 | BK7: 0.26574361 | BL7: NA | BM7: NA | BN7: NA | BO7: NA | BP7: NA | BQ7: NA | BR7: NA | BS7: NA
B8: Canara Rob Bluechip Equity Fund-Reg(G) | C8: 1.64 | D8: 45838 | E8: 16617.33 | F8: -0.022278 | G8: 0.029528 | H8: 0.065354 | I8: 0.018666 | J8: 0.161045 | K8: 0.186387 | L8: 0.131291 | N8: 0.039245 | O8: 0.1778818 | P8: 0.22216925 | Q8: 0.0081711127 | R8: 0.2454355 | S8: 0.2305709 | T8: 0.15679591 | U8: 0.033920705 | V8: 0.31365741 | W8: 0.018867925 | X8: -0.0046948357 | Y8: 0.35885167 | Z8: 0.050251256 | AA8: 0.28387097 | AB8: -0.12757974 | AC8: 0.066 | AD8: NA | AE8: NA | AF8: NA | AG8: NA | AH8: NA | AI8: NA | AJ8: NA | AK8: NA | AL8: NA | AM8: NA | AN8: 0.7 | AO8: 0.9 | AP8: 26.79 | AQ8: 4.13 | AS8: Inquant Debt Plus AIF | AX8: NA | AY8: NA | AZ8: NA | BA8: NA | BB8: NA | BC8: NA | BD8: NA | BF8: NA | BG8: NA | BH8: NA | BI8: NA | BJ8: NA | BK8: NA | BL8: NA | BM8: NA | BN8: NA | BO8: NA | BP8: NA | BQ8: NA | BR8: NA | BS8: NA
B9: DSP Top 100 Equity Fund-Reg(G) | C9: 1.85 | D9: 45838 | E9: 6323.2679 | F9: -0.021492 | G9: 0.01465 | H9: 0.06126 | I9: 0.01562 | J9: 0.185538 | K9: 0.1903 | L9: 0.110868 | N9: 0.044684 | O9: 0.2049885 | P9: 0.26612783 | Q9: 0.014408547 | R9: 0.19525391 | S9: 0.074924487 | T9: 0.14845194 | U9: -0.027213439 | V9: 0.26480237 | W9: 0.048876567 | X9: -0.023289758 | Y9: 0.37488338 | Z9: 0.022260212 | AA9: 0.30285446 | AB9: -0.19847974 | AC9: 0.16797076 | AD9: 0.77127029 | AE9: -0.45541253 | AF9: 0.6493121 | AG9: 0.46598413 | AH9: 0.4290417 | AI9: 0.25011431 | AJ9: 1.187 | AK9: NA | AL9: NA | AM9: NA | AS9: AlphaMine Absolute Return Fund | AX9: 0.0022 | AY9: 0.021370082 | AZ9: 0.021131767 | BA9: 0.1080265 | BB9: 0.15702444 | BC9: NA | BD9: NA | BF9: 0.0050281603 | BG9: 0.16725751 | BH9: 0.1692687 | BI9: 0.13371028 | BJ9: NA | BK9: NA | BL9: NA | BM9: NA | BN9: NA | BO9: NA | BP9: NA | BQ9: NA | BR9: NA | BS9: NA
B10: Edelweiss Large Cap Fund-Reg(G) | C10: 2.11 | D10: 45838 | E10: 1322.0746 | F10: -0.03389 | G10: 0.017227 | H10: 0.042103 | I10: -0.030946 | J10: 0.158246 | K10: 0.184889 | L10: 0.118923 | N10: 0.018229 | O10: 0.14626571 | P10: 0.2571885 | Q10: 0.033761468 | R10: 0.23386914 | S10: 0.17286245 | T10: 0.115191 | U10: 0.016862391 | V10: 0.33803384 | W10: 0.0040453074 | X10: 0.0077456176 | Y10: 0.37654321 | Z10: 0.11097257 | AA10: 0.29773463 | AB10: -0.18577075 | AC10: 0.15966387 | AD10: 0.309 | AE10: NA | AF10: NA | AG10: NA | AH10: NA | AI10: NA | AJ10: NA | AK10: NA | AL10: NA | AM10: NA | AS10: MasterTrust Irage PMS | AX10: 0.0126 | AY10: 0.037250583 | AZ10: 0.079266509 | BA10: 0.17013075 | BB10: 0.13529855 | BC10: 0.12846998 | BF10: 0.054468942 | BG10: 0.1706778 | BH10: 0.10516945 | BI10: 0.092774729 | BJ10: 0.10082501 | BK10: 0.16216316 | BL10: 0.11393722 | BM10: 0.12732582 | BN10: 0.13211315 | BO10: NA | BP10: NA | BQ10: NA | BR10: NA | BS10: NA
B11: Franklin India Bluechip Fund(G) | C11: 1.84 | D11: 45838 | E11: 7983.816 | F11: -0.019053 | G11: 0.036704 | H11: 0.069894 | I11: 0.013708 | J11: 0.146926 | K11: 0.195552 | L11: 0.107427 | N11: 0.040589 | O11: 0.16213533 | P11: 0.21660848 | Q11: -0.022212752 | R11: 0.32758244 | S11: 0.13670259 | T11: 0.052560253 | U11: -0.035776523 | V11: 0.26308045 | W11: 0.064457763 | X11: 0.020175124 | Y11: 0.37221097 | Z11: 0.040781877 | AA11: 0.26788334 | AB11: -0.18248512 | AC11: 0.2296256 | AD11: 0.8448816 | AE11: -0.48142429 | AF11: 0.47408066 | AG11: 0.45523873 | AH11: 0.4122054 | AI11: 0.24601322 | AJ11: 1.2059202 | AK11: 0.23923445 | AL11: -0.16139099 | AM11: -0.13196594 | AS11: Vivriti Short-term Debt AIF
B12: HDFC Top 100 Fund(G) | C12: 1.59 | D12: 45838 | E12: 38905.124 | F12: -0.02065 | G12: 0.018871 | H12: 0.049209 | I12: -0.02436 | J12: 0.171713 | K12: 0.215781 | L12: 0.12449 | N12: 0.033793 | O12: 0.11644625 | P12: 0.30023194 | Q12: 0.10611136 | R12: 0.28536696 | S12: 0.059106121 | T12: 0.076981707 | U12: 0.0012633068 | V12: 0.31966805 | W12: 0.085208398 | X12: -0.060898105 | Y12: 0.46517644 | Z12: 0.040487798 | AA12: 0.32433239 | AB12: -0.24296179 | AC12: 0.25050428 | AD12: 0.94461088 | AE12: -0.45345427 | AF12: 0.54452834 | AG12: 0.37446862 | AH12: 0.55240683 | AI12: 0.27524752 | AJ12: 1.3447475 | AK12: 0.261347 | AL12: -0.10131579 | AM12: -0.21082294 | AS12: ICICI CCOF 3
B13: HSBC Large Cap Fund(G) | C13: 2.13 | D13: 45838 | E13: 1887.7311 | F13: -0.01841 | G13: 0.02958 | H13: 0.036813 | I13: -0.026154 | J13: 0.146284 | K13: 0.176785 | L13: 0.117438 | N13: -0.00662 | O13: 0.18323184 | P13: 0.2351433 | Q13: 0.0051164687 | R13: 0.22700806 | S13: 0.15854095 | T13: 0.15106851 | U13: -0.031707561 | V13: 0.30534337 | W13: 0.080212173 | X13: -0.029875145 | Y13: 0.34854924 | Z13: 0.031850503 | AA13: 0.23237926 | AB13: -0.22681756 | AC13: 0.17997841 | AD13: 0.58548056 | AE13: -0.480475 | AF13: 0.59525125 | AG13: 0.37249896 | AH13: 0.41968203 | AI13: 0.38730957 | AJ13: 1.6025391 | AK13: 0.024 | AL13: NA | AM13: NA | AS13: Vivriti Diversified Bond Fund II
B14: ICICI Pru Bluechip Fund(G) | C14: 1.42 | D14: 45838 | E14: 72336.051 | F14: -0.016662 | G14: 0.029834 | H14: 0.071031 | I14: 0.011239 | J14: 0.189794 | K14: 0.221221 | L14: 0.137519 | N14: 0.057922 | O14: 0.1687317 | P14: 0.27392739 | Q14: 0.068537259 | R14: 0.29174094 | S14: 0.13486177 | T14: 0.097705403 | U14: -0.0080763583 | V14: 0.32748538 | W14: 0.077353868 | X14: -0.0020957038 | Y14: 0.41103992 | Z14: 0.10211841 | AA14: 0.26790634 | AB14: -0.16407599 | AC14: 0.27066569 | AD14: 0.91188811 | AE14: -0.285 | AF14: NA | AG14: NA | AH14: NA | AI14: NA | AJ14: NA | AK14: NA | AL14: NA | AM14: NA | AN14: 0.9 | AO14: 0.89 | AP14: 22.93 | AQ14: 3.49 | AS14: UTI SDOF 4
B15: Invesco India Largecap Fund(G) | C15: 2.05 | D15: 45838 | E15: 1558.2449 | F15: -0.034711 | G15: 0.036672 | H15: 0.070412 | I15: -0.002188 | J15: 0.170622 | K15: 0.191028 | L15: 0.121877 | N15: 0.017854 | O15: 0.19996429 | P15: 0.27789185 | Q15: -0.029880478 | R15: 0.32531534 | S15: 0.14051522 | T15: 0.10499076 | U15: -0.004416636 | V15: 0.28341993 | W15: 0.027669903 | X15: 0.045685279 | Y15: 0.39518414 | Z15: 0.092034029 | AA15: 0.24326923 | AB15: -0.21921922 | AC15: 0.17667845 | AD15: 0.132 | AE15: NA | AF15: NA | AG15: NA | AH15: NA | AI15: NA | AJ15: NA | AK15: NA | AL15: NA | AM15: NA | AS15: Edelweiss Multi Asset Allocation Fund | AX15: 0.0148 | AY15: 0.0283 | AZ15: 0.0472 | BA15: 0.0912 | BB15: NA | BC15: NA | BD15: NA | BF15: 0.0335 | BG15: 0.071 | BH15: 0.0358 | BI15: NA | BJ15: NA | BK15: NA | BL15: NA | BM15: NA | BN15: NA | BO15: NA | BP15: NA | BQ15: NA | BR15: NA | BS15: NA | BT15: NA | BU15: NA
B16: Kotak Bluechip Fund(G) | C16: 1.73 | D16: 45838 | E16: 10515.746 | F16: -0.022727 | G16: 0.035144 | H16: 0.067235 | I16: -0.00366 | J16: 0.159149 | K16: 0.193198 | L16: 0.121931 | N16: 0.038292 | O16: 0.16245345 | P16: 0.22901642 | Q16: 0.019884268 | R16: 0.27737167 | S16: 0.16371431 | T16: 0.14195371 | U16: -0.021050815 | V16: 0.29177695 | W16: 0.0293261 | X16: 0.037691265 | Y16: 0.42456531 | Z16: 0.042604903 | AA16: 0.23411042 | AB16: -0.18461974 | AC16: 0.16290817 | AD16: 0.66706767 | AE16: -0.50345233 | AF16: 0.66563268 | AG16: 0.4361302 | AH16: 0.49369115 | AI16: 0.36761676 | AJ16: 0.93600931 | AK16: NA | AL16: NA | AM16: NA | AN16: 0.65 | AO16: 0.93 | AP16: 23.66 | AQ16: 3.61 | AS16: Aditya Birla SL Banking & PSU Debt(G) | AT16: 0.73 | AU16: 45716 | AV16: 9585.9669 | AX16: 0.013215 | AY16: 0.022823 | AZ16: 0.038488 | BA16: 0.081713 | BB16: 0.065641 | BC16: 0.06502 | BD16: 0.075168 | BF16: 0.022823 | BG16: 0.078779361 | BH16: 0.068615907 | BI16: 0.0365218 | BJ16: 0.03585331 | BK16: 0.10912871 | BL16: 0.099015785 | BM16: 0.066298122 | BN16: 0.056139229 | BO16: 0.12320145 | BP16: 0.085202932 | BQ16: 0.12471321 | BR16: 0.096338822 | BS16: 0.098549163 | BT16: 0.09254704 | BU16: 0.058149316
B17: Mirae Asset Large Cap Fund-Reg(G) | C17: 1.51 | D17: 45838 | E17: 40724.594 | F17: -0.016011 | G17: 0.040576 | H17: 0.074604 | I17: 0.009309 | J17: 0.134872 | K17: 0.176536 | L17: 0.127192 | N17: 0.049824 | O17: 0.12685662 | P17: 0.18449936 | Q17: 0.015984371 | R17: 0.27735736 | S17: 0.13702694 | T17: 0.12725611 | U17: -0.0063769193 | V17: 0.38580335 | W17: 0.080898946 | X17: 0.042540849 | Y17: 0.52859747 | Z17: 0.089469729 | AA17: 0.33276109 | AB17: -0.19641317 | AC17: 0.23121019 | AD17: 1.0933333 | AE17: -0.325 | AF17: NA | AG17: NA | AH17: NA | AI17: NA | AJ17: NA | AK17: NA | AL17: NA | AM17: NA | AS17: Axis Banking & PSU Debt Fund-Reg(G) | AT17: 0.63 | AU17: 45716 | AV17: 12987.924 | AX17: 0.012468 | AY17: 0.023066 | AZ17: 0.039291 | BA17: 0.080002 | BB17: 0.064007 | BC17: 0.061721 | BD17: 0.072638 | BF17: 0.023066 | BG17: 0.075549841 | BH17: 0.065271973 | BI17: 0.037538678 | BJ17: 0.033896428 | BK17: 0.095916205 | BL17: 0.10523663 | BM17: 0.0756194 | BN17: 0.071828814 | BO17: 0.083710786 | BP17: 0.084982704 | BQ17: 0.09271979 | BR17: 0.086891331 | BS17: 0.0518253 | BT17: NA | BU17: NA
B18: Motilal Oswal Focused Fund-Reg(G) | C18: 2.14 | D18: 45838 | E18: 1563.5841 | F18: -0.015099 | G18: 0.118679 | H18: 0.064219 | I18: -0.110031 | J18: 0.106595 | K18: 0.137627 | L18: 0.097715 | N18: -0.037661 | O18: 0.1361965 | P18: 0.18819264 | Q18: 0.01953572 | R18: 0.14587881 | S18: 0.1727827 | T18: 0.17085497 | U18: -0.042033905 | V18: 0.32153901 | W18: 0.028329039 | X18: 0.058967585 | Y18: 0.44235624 | Z18: 0.04183 | AA18: NA | AB18: NA | AC18: NA | AD18: NA | AE18: NA | AF18: NA | AG18: NA | AH18: NA | AI18: NA | AJ18: NA | AK18: NA | AL18: NA | AM18: NA | AS18: Bajaj Finserv Banking and PSU Fund-Reg(G) | AT18: 0.89 | AU18: 45716 | AV18: 118.4179 | AX18: 0.013812 | AY18: 0.023175 | AZ18: 0.037051 | BA18: 0.080731 | BB18: NA | BC18: NA | BD18: NA | BF18: 0.023175 | BG18: 0.078089004 | BH18: 0.01141 | BI18: NA | BJ18: NA | BK18: NA | BL18: NA | BM18: NA | BN18: NA | BO18: NA | BP18: NA | BQ18: NA | BR18: NA | BS18: NA | BT18: NA | BU18: NA
B19: Nippon India Large Cap Fund(G) | C19: 1.51 | D19: 45838 | E19: 43828.6 | F19: -0.017875 | G19: 0.047609 | H19: 0.078495 | I19: 0.006832 | J19: 0.204123 | K19: 0.251486 | L19: 0.137065 | N19: 0.045961 | O19: 0.18239725 | P19: 0.32147843 | Q19: 0.11327834 | R19: 0.32367195 | S19: 0.049081268 | T19: 0.072519095 | U19: -0.0020039659 | V19: 0.38421195 | W19: 0.022273823 | X19: 0.01114297 | Y19: 0.54645567 | Z19: 0.041530123 | AA19: 0.40968364 | AB19: -0.26445203 | AC19: 0.19364058 | AD19: 0.73425141 | AE19: -0.49161838 | AF19: 0.32552 | AG19: NA | AH19: NA | AI19: NA | AJ19: NA | AK19: NA | AL19: NA | AM19: NA | AN19: 0.97 | AO19: 0.93 | AP19: 23.34 | AQ19: 3.48 | AS19: Bandhan Banking & PSU Debt Fund-Reg(G) | AT19: 0.63 | AU19: 45716 | AV19: 13421.371 | AX19: 0.011061 | AY19: 0.021775 | AZ19: 0.037649 | BA19: 0.079011 | BB19: 0.063857 | BC19: 0.063167 | BD19: 0.072341 | BF19: 0.021775 | BG19: 0.075793573 | BH19: 0.067378924 | BI19: 0.03619234 | BJ19: 0.034072003 | BK19: 0.10928488 | BL19: 0.11201107 | BM19: 0.07349549 | BN19: 0.055009909 | BO19: 0.07992761 | BP19: 0.08540439 | BQ19: 0.092553023 | BR19: 0.07171 | BS19: NA | BT19: NA | BU19: NA
B20: Quant Large Cap Fund-Reg(G) | C20: 1.9 | D20: 45838 | E20: 2753.2825 | F20: -0.025314 | G20: 0.065384 | H20: 0.045383 | I20: -0.070916 | J20: NA | K20: NA | L20: NA | N20: 0.015821 | O20: 0.14180552 | P20: 0.2684703 | Q20: 0.01203 | R20: NA | S20: NA | T20: NA | U20: NA | V20: NA | W20: NA | X20: NA | Y20: NA | Z20: NA | AA20: NA | AB20: NA | AC20: NA | AD20: NA | AE20: NA | AF20: NA | AG20: NA | AH20: NA | AI20: NA | AJ20: NA | AK20: NA | AL20: NA | AM20: NA | AS20: Baroda BNP Paribas Banking and PSU Bond Fund-Reg(G) | AT20: 0.79 | AU20: 45716 | AV20: 25.4039 | AX20: 0.014231 | AY20: 0.023712 | AZ20: 0.038273 | BA20: 0.079998 | BB20: 0.057487 | BC20: NA | BD20: NA | BF20: 0.023712 | BG20: 0.078167958 | BH20: 0.062874166 | BI20: 0.016991509 | BJ20: 0.03417652 | BK20: 0.00215 | BL20: NA | BM20: NA | BN20: NA | BO20: NA | BP20: NA | BQ20: NA | BR20: NA | BS20: NA | BT20: NA | BU20: NA
B21: SBI BlueChip Fund-Reg(G) | C21: 1.48 | D21: 45838 | E21: 53959.081 | F21: -0.019714 | G21: 0.034552 | H21: 0.066194 | I21: 0.010644 | J21: 0.151055 | K21: 0.195883 | L21: 0.121038 | N21: 0.050959 | O21: 0.12452086 | P21: 0.22621771 | Q21: 0.043574375 | R21: 0.26083199 | S21: 0.16339437 | T21: 0.116371 | U21: -0.041095749 | V21: 0.30229212 | W21: 0.048280784 | X21: 0.079896741 | Y21: 0.47858033 | Z21: 0.075809179 | AA21: 0.38230384 | AB21: -0.24225174 | AC21: 0.11889597 | AD21: 0.87898936 | AE21: -0.55023923 | AF21: 0.42783945 | AG21: 0.171 | AH21: NA | AI21: NA | AJ21: NA | AK21: NA | AL21: NA | AM21: NA | AS21: Canara Rob Banking and PSU Debt Fund-Reg(G) | AT21: 0.71 | AU21: 45716 | AV21: 230.0894 | AX21: 0.010766 | AY21: 0.020533 | AZ21: 0.035901 | BA21: 0.076772 | BB21: NA | BC21: NA | BD21: NA | BF21: 0.020533 | BG21: 0.076620388 | BH21: 0.06217162 | BI21: 0.01445 | BJ21: NA | BK21: NA | BL21: NA | BM21: NA | BN21: NA | BO21: NA | BP21: NA | BQ21: NA | BR21: NA | BS21: NA | BT21: NA | BU21: NA
B22: Tata Large Cap Fund-Reg(G) | C22: 2 | D22: 45838 | E22: 2701.7776 | F22: -0.029866 | G22: 0.018921 | H22: 0.042854 | I22: -0.041784 | J22: 0.149555 | K22: 0.193573 | L22: 0.111409 | N22: 0.023155 | O22: 0.12893307 | P22: 0.2453916 | Q22: 0.033117279 | R22: 0.32670901 | S22: 0.08334113 | T22: 0.12105105 | U22: -0.036483489 | V22: 0.29538417 | W22: 0.028963337 | X22: 0.013384043 | Y22: 0.36047873 | Z22: 0.079618712 | AA22: 0.28467119 | AB22: -0.21223889 | AC22: 0.18954593 | AD22: 0.77176028 | AE22: -0.49213696 | AF22: 0.61319394 | AG22: 0.42628928 | AH22: 0.44354235 | AI22: 0.29280003 | AJ22: 1.4064585 | AK22: 0.063867887 | AL22: -0.23847844 | AM22: -0.065964847 | AS22: DSP Banking & PSU Debt Fund-Reg(G) | AT22: 0.72 | AU22: 45716 | AV22: 3211.4465 | AX22: 0.016883 | AY22: 0.022519 | AZ22: 0.034762 | BA22: 0.083187 | BB22: 0.066645 | BC22: 0.06364 | BD22: 0.072591 | BF22: 0.022519 | BG22: 0.086378863 | BH22: 0.06710311 | BI22: 0.032067856 | BJ22: 0.031010941 | BK22: 0.10900991 | BL22: 0.099235448 | BM22: 0.063312352 | BN22: 0.054202619 | BO22: 0.10610844 | BP22: 0.085978604 | BQ22: 0.10421488 | BR22: 0.03277 | BS22: NA | BT22: NA | BU22: NA
B23: UTI Mastershare-Reg(G) | C23: 1.74 | D23: 45838 | E23: 13074.263 | F23: -0.023264 | G23: 0.022039 | H23: 0.047724 | I23: -0.009849 | J23: 0.13088 | K23: 0.178196 | L23: 0.112141 | N23: 0.040083 | O23: 0.11214977 | P23: 0.20781484 | Q23: -0.017947658 | R23: 0.29562368 | S23: 0.18671586 | T23: 0.10691731 | U23: -0.0038844725 | V23: 0.29572189 | W23: 0.036009266 | X23: -0.0048597755 | Y23: 0.43292567 | Z23: 0.059010932 | AA23: 0.25065104 | AB23: -0.19721254 | AC23: 0.18472652 | AD23: 0.74155284 | AE23: -0.5030368 | AF23: 0.62543554 | AG23: 0.2699115 | AH23: 0.17606245 | AI23: NA | AJ23: NA | AK23: NA | AL23: NA | AM23: NA | AS23: Edelweiss Banking and PSU Debt Fund-Reg(G) | AT23: 0.7 | AU23: 45716 | AV23: 263.6194 | AX23: 0.016354 | AY23: 0.025413 | AZ23: 0.03911 | BA23: 0.084519 | BB23: 0.06375 | BC23: 0.065044 | BD23: 0.07529 | BF23: 0.025413 | BG23: 0.081863013 | BH23: 0.063965145 | BI23: 0.025818264 | BJ23: 0.045303201 | BK23: 0.12919269 | BL23: 0.12921882 | BM23: 0.058581226 | BN23: 0.060058821 | BO23: 0.08035859 | BP23: 0.083360409 | BQ23: 0.10752458 | BR23: 0.02823 | BS23: NA | BT23: NA | BU23: NA
B24: UTI Nifty 50 ETF | C24: 0.05 | D24: 45838 | E24: 64150.21 | F24: -0.027639 | G24: 0.024295 | H24: 0.061562 | I24: 0.004964 | J24: 0.142216 | K24: 0.187925 | L24: NA | N24: 0.056746 | O24: 0.099910956 | P24: 0.2125411 | Q24: 0.056157732 | R24: 0.25494746 | S24: 0.15693706 | T24: 0.13453962 | U24: 0.045280136 | V24: 0.30309359 | W24: 0.046780383 | X24: 0.021939998 | Y24: NA | Z24: NA | AA24: NA | AB24: NA | AC24: NA | AD24: NA | AE24: NA | AF24: NA | AG24: NA | AH24: NA | AI24: NA | AJ24: NA | AK24: NA | AL24: NA | AM24: NA | AS24: Franklin India Banking & PSU Debt Fund(G) | AT24: 0.51 | AU24: 45716 | AV24: 587.34295 | AX24: 0.010765 | AY24: 0.020875 | AZ24: 0.037637 | BA24: 0.078652 | BB24: 0.063335 | BC24: 0.058892 | BD24: 0.071208 | BF24: 0.020875 | BG24: 0.077025991 | BH24: 0.06836225 | BI24: 0.032700515 | BJ24: 0.036923236 | BK24: 0.091325972 | BL24: 0.11195748 | BM24: 0.068597935 | BN24: 0.0633893 | BO24: 0.096554414 | BP24: 0.072633957 | BQ24: 0.07553 | BR24: NA | BS24: NA | BT24: NA | BU24: NA
B25: S&P BSE 100 | F25: -0.029931 | G25: 0.023115 | H25: 0.054214 | I25: -0.018044 | J25: 0.139445 | K25: 0.183864 | L25: 0.11603 | N25: 0.035912 | O25: 0.11958334 | P25: 0.21490819 | Q25: 0.045369467 | R25: 0.2499945 | S25: 0.15235788 | T25: 0.096332593 | U25: 0.011898696 | V25: 0.31515294 | W25: 0.035704539 | X25: -0.032464002 | Y25: 0.32284501 | Z25: 0.058734148 | AA25: 0.29957962 | AB25: -0.25733626 | AC25: 0.15659331 | AD25: 0.8503695 | AE25: -0.55281414 | AF25: 0.5974498 | AG25: 0.40968359 | AH25: 0.38346335 | AI25: 0.16439201 | AJ25: 0.84712742 | AK25: 0.068999878 | AL25: -0.23372756 | AM25: -0.22567337 | AS25: HDFC Banking and PSU Debt Fund-Reg(G) | AT25: 0.74 | AU25: 45716 | AV25: 5836.8354 | AX25: 0.013555 | AY25: 0.022796 | AZ25: 0.038329 | BA25: 0.080927 | BB25: 0.064865 | BC25: 0.063823 | BD25: 0.073895 | BF25: 0.022796 | BG25: 0.078520718 | BH25: 0.068312675 | BI25: 0.032786797 | BJ25: 0.036586459 | BK25: 0.1056561 | BL25: 0.10229267 | BM25: 0.05868105 | BN25: 0.063229348 | BO25: 0.10829762 | BP25: 0.09755094 | BQ25: 0.06939 | BR25: NA | BS25: NA | BT25: NA | BU25: NA
B26: S&P BSE SENSEX | F26: -0.028956 | G26: 0.011756 | H26: 0.047548 | I26: -0.006799 | J26: 0.121048 | K26: 0.166288 | L26: 0.111775 | N26: 0.038989 | O26: 0.081654606 | P26: 0.18736656 | Q26: 0.044407732 | R26: 0.21994131 | S26: 0.15750305 | T26: 0.14376629 | U26: 0.059063043 | V26: 0.27905963 | W26: 0.019485756 | X26: -0.050251242 | Y26: 0.29893891 | Z26: 0.089771763 | AA26: 0.25699195 | AB26: -0.2464356 | AC26: 0.17430937 | AD26: 0.81032951 | AE26: -0.52445829 | AF26: 0.4714675 | AG26: 0.46701561 | AH26: 0.42334867 | AI26: 0.13079898 | AJ26: 0.72889426 | AK26: 0.035235553 | AL26: -0.17869299 | AM26: -0.20649963 | AS26: HSBC Banking and PSU Debt Fund-Reg(G) | AT26: 0.61 | AU26: 45716 | AV26: 4246.1157 | AX26: 0.012191 | AY26: 0.021556 | AZ26: 0.038828 | BA26: 0.075843 | BB26: 0.054725 | BC26: 0.056754 | BD26: 0.067779 | BF26: 0.021556 | BG26: 0.07264331 | BH26: 0.064940755 | BI26: 0.015603596 | BJ26: 0.030324884 | BK26: 0.10399559 | BL26: 0.095724131 | BM26: 0.062456967 | BN26: 0.054782372 | BO26: 0.10265571 | BP26: 0.077445742 | BQ26: 0.087094941 | BR26: 0.082094723 | BS26: 0.02467 | BT26: -0.19711604 | BU26: 0.056932163
B27: NIFTY 50 | F27: -0.029341 | G27: 0.017841 | H27: 0.053596 | I27: -0.007326 | J27: 0.129786 | K27: 0.174585 | L27: 0.112352 | N27: 0.047518 | O27: 0.08804769 | P27: 0.20027839 | Q27: 0.043289607 | R27: 0.24119298 | S27: 0.14901651 | T27: 0.12022039 | U27: 0.031512625 | V27: 0.28645948 | W27: 0.030133332 | X27: -0.040608739 | Y27: 0.31388008 | Z27: 0.067551777 | AA27: 0.27697165 | AB27: -0.24618143 | AC27: 0.17947338 | AD27: 0.75761621 | AE27: -0.51794383 | AF27: 0.54765026 | AG27: 0.39831838 | AH27: 0.36339822 | AI27: 0.10679612 | AJ27: 0.71902149 | AK27: 0.032529153 | AL27: -0.16184559 | AM27: -0.14650951 | AS27: ICICI Pru Banking & PSU Debt Fund(G) | AT27: 0.74 | AU27: 45716 | AV27: 10092.248 | AX27: 0.011755 | AY27: 0.022022 | AZ27: 0.041196 | BA27: 0.080557 | BB27: 0.070255 | BC27: 0.06704 | BD27: 0.074984 | BF27: 0.022022 | BG27: 0.078957058 | BH27: 0.07315605 | BI27: 0.042694925 | BJ27: 0.042201238 | BK27: 0.092877505 | BL27: 0.10104015 | BM27: 0.057176113 | BN27: 0.056228364 | BO27: 0.12621984 | BP27: 0.086427002 | BQ27: 0.10496887 | BR27: 0.0892704 | BS27: 0.088708492 | BT27: 0.091194672 | BU27: 0.06004
B28: NIFTY NEXT 50 | F28: -0.027567 | G28: 0.040108 | H28: 0.06287 | I28: -0.10285 | J28: 0.178801 | K28: 0.200799 | L28: 0.124071 | N28: -0.013123 | O28: 0.27450752 | P28: 0.26446486 | Q28: -0.00071652072 | R28: 0.29867066 | S28: 0.14840564 | T28: 0.0045690377 | U28: -0.089968722 | V28: 0.44764302 | W28: 0.070713644 | X28: 0.069566917 | Y28: 0.44416137 | Z28: 0.048071118 | AA28: 0.48084746 | AB28: -0.3187487 | AC28: 0.17811841 | AD28: 1.279057 | AE28: -0.63520109 | AF28: 0.75733675 | AG28: 0.28239901 | AH28: 0.24434689 | AI28: 0.30760196 | AJ28: 1.4101766 | AK28: 0.088384811 | AL28: -0.46485027 | AM28: -0.39102114 | AS28: Invesco India Banking and PSU Fund(G) | AT28: 0.63 | AU28: 45716 | AV28: 100.2439 | AX28: 0.014095 | AY28: 0.02258 | AZ28: 0.036818 | BA28: 0.080816 | BB28: 0.057694 | BC28: 0.05639 | BD28: 0.064037 | BF28: 0.02258 | BG28: 0.082240309 | BH28: 0.064597532 | BI28: 0.00706597 | BJ28: 0.034208574 | BK28: 0.094919563 | BL28: 0.096750438 | BM28: 0.0717279 | BN28: 0.048873987 | BO28: 0.074099591 | BP28: 0.068512537 | BQ28: 0.08702073 | BR28: 0.071080341 | BS28: 0.0021083 | BT28: NA | BU28: NA
B29: Category Average | F29: =AVERAGE(F5:F24) -> -0.022027 | G29: =AVERAGE(G5:G24) -> 0.0360513 | H29: =AVERAGE(H5:H24) -> 0.061447 | I29: =AVERAGE(I5:I24) -> -0.010452 | J29: =AVERAGE(J5:J24) -> 0.15538732 | K29: =AVERAGE(K5:K24) -> 0.18994768 | L29: =AVERAGE(L5:L24) -> 0.11975772 | N29: =AVERAGE(N5:N24) -> 0.0321049 | O29: =AVERAGE(O5:O24) -> 0.15274136 | P29: =AVERAGE(P5:P24) -> 0.24029144 | Q29: =AVERAGE(Q5:Q24) -> 0.021761015 | R29: =AVERAGE(R5:R24) -> 0.26562762 | S29: =AVERAGE(S5:S24) -> 0.14392638 | T29: =AVERAGE(T5:T24) -> 0.11911939 | U29: =AVERAGE(U5:U24) -> -0.0088778563 | ... AM29: =AVERAGE(AM5:AM24) -> -0.13625125 | AS29: ITI Banking & PSU Debt Fund-Reg(G) | AT29: 0.7 | AU29: 45716 | AV29: 30.5653 | AX29: 0.010283 | AY29: 0.02064 | AZ29: 0.036304 | BA29: 0.073687 | BB29: 0.064727 | BC29: NA | BD29: NA | BF29: 0.02064 | BG29: 0.076071804 | BH29: 0.062999113 | BI29: 0.042433894 | BJ29: 0.036347106 | BK29: 0.01191 | BL29: NA | BM29: NA | BN29: NA | BO29: NA | BP29: NA | BQ29: NA | BR29: NA | BS29: NA | BT29: NA | BU29: NA
AS30: Kotak Banking and PSU Debt Fund(G) | AT30: 0.75 | AU30: 45716 | AV30: 5761.9869 | AX30: 0.013049 | AY30: 0.022182 | AZ30: 0.037352 | BA30: 0.08135 | BB30: 0.066035 | BC30: 0.064847 | BD30: 0.074685 | BF30: 0.022182 | BG30: 0.080312307 | BH30: 0.067708017 | BI30: 0.03598099 | BJ30: 0.039126906 | BK30: 0.10506663 | BL30: 0.10843988 | BM30: 0.06714405 | BN30: 0.061701811 | BO30: 0.099623332 | BP30: 0.085634079 | BQ30: 0.095126499 | BR30: 0.098275814 | BS30: 0.076329608 | BT30: 0.078518124 | BU30: 0.036520796
AS31: LIC MF Banking & PSU Fund-Reg(G) | AT31: 0.78 | AU31: 45716 | AV31: 1881.9096 | AX31: 0.014643 | AY31: 0.023844 | AZ31: 0.038255 | BA31: 0.080928 | BB31: 0.06325 | BC31: 0.057687 | BD31: 0.066254 | BF31: 0.023844 | BG31: 0.077791605 | BH31: 0.065089002 | BI31: 0.030611229 | BJ31: 0.025743384 | BK31: 0.085582659 | BL31: 0.098575246 | BM31: 0.072010375 | BN31: 0.061304313 | BO31: 0.081421435 | BP31: 0.059928835 | BQ31: 0.075218755 | BR31: 0.08085185 | BS31: 0.087324125 | BT31: 0.082495595 | BU31: 0.054709056
B32: Large-Mid | C32: Expense Ratio | D32: Corpus | F32: Returns | N32: CY Year Returns | AS32: Mirae Asset Banking and PSU Fund-Reg(G) | AT32: 0.81 | AU32: 45716 | AV32: 47.918026 | AX32: 0.013688 | AY32: 0.022021 | AZ32: 0.03885 | BA32: 0.079619 | BB32: 0.061269 | BC32: NA | BD32: NA | BF32: 0.022021 | BG32: 0.079484416 | BH32: 0.063178613 | BI32: 0.026726755 | BJ32: 0.033911107 | BK32: 0.01943 | BL32: NA | BM32: NA | BN32: NA | BO32: NA | BP32: NA | BQ32: NA | BR32: NA | BS32: NA | BT32: NA | BU32: NA
D33: Month End | E33: AUM (Cr.) | F33: 1 month | G33: 3 months | H33: 6 months | I33: 1 Year | J33: 3 Year | K33: 5 Year | L33: 10 Year | N33: CY 2025 | O33: 2024 | P33: 2023 | Q33: 2022 | R33: 2021 | S33: 2020 | T33: 2019 | U33: 2018 | V33: 2017 | W33: 2016 | X33: 2015 | Y33: 2014 | Z33: 2013 | AA33: 2012 | AB33: 2011 | AC33: 2010 | AD33: 2009 | AE33: 2008 | AF33: 2007 | AG33: 2006 | AH33: 2005 | AI33: 2004 | AJ33: 2003 | AK33: 2002 | AL33: 2001 | AM33: 2000 | AS33: Nippon India Banking & PSU Debt Fund(G) | AT33: 0.76 | AU33: 45716 | AV33: 5708.448 | AX33: 0.014032 | AY33: 0.023173 | AZ33: 0.037979 | BA33: 0.080922 | BB33: 0.064005 | BC33: 0.064171 | BD33: NA | BF33: 0.023173 | BG33: 0.078521199 | BH33: 0.067979872 | BI33: 0.03169927 | BJ33: 0.038587829 | BK33: 0.10930828 | BL33: 0.1049394 | BM33: 0.064093829 | BN33: 0.059584891 | BO33: 0.10176312 | BP33: 0.05608 | BQ33: NA | BR33: NA | BS33: NA | BT33: NA | BU33: NA
B34: Aditya Birla SL Equity Advantage Fund(G) | C34: 1.89 | D34: 45838 | E34: 5938.6697 | F34: -0.029179 | G34: 0.059811 | H34: 0.070842 | I34: -0.034068 | J34: 0.145022 | K34: 0.186091 | L34: 0.112275 | N34: 0.009438 | O34: 0.15576279 | P34: 0.26927419 | Q34: -0.12981422 | R34: 0.3826978 | S34: 0.18301905 | T34: 0.089126239 | U34: -0.13718828 | V34: 0.41845156 | W34: 0.084771244 | X34: 0.052353385 | Y34: 0.60146263 | Z34: 0.072240059 | AA34: 0.29713279 | AB34: -0.28030434 | AC34: 0.14394039 | AD34: 0.8728081 | AE34: -0.58375739 | AF34: 0.5654168 | AG34: 0.34385813 | AH34: 0.43246592 | AI34: 0.26936689 | AJ34: 1.1033912 | AK34: 0.033333333 | AL34: -0.23902439 | AM34: -0.46091292 | AS34: SBI Banking and PSU Fund-Reg(G) | AT34: 0.81 | AU34: 45716 | AV34: 3873.701 | AX34: 0.013412 | AY34: 0.022945 | AZ34: 0.037474 | BA34: 0.079409 | BB34: 0.06153 | BC34: 0.059747 | BD34: 0.070359 | BF34: 0.022945 | BG34: 0.076853266 | BH34: 0.065570524 | BI34: 0.028668579 | BJ34: 0.02584904 | BK34: 0.10470041 | BL34: 0.096694565 | BM34: 0.073631934 | BN34: 0.063865533 | BO34: 0.083349621 | BP34: 0.087326405 | BQ34: 0.10015413 | BR34: 0.083364702 | BS34: 0.090831264 | BT34: 0.088368946 | BU34: 0.055658927
B35: Axis Growth Opp Fund-Reg(G) | C35: 1.68 | D35: 45838 | E35: 14954.276 | F35: -0.016359 | G35: 0.06459 | H35: 0.065289 | I35: 0.009012 | J35: 0.178521 | K35: 0.227601 | L35: NA | N35: 0.014054 | O35: 0.25519404 | P35: 0.30954825 | Q35: -0.088868101 | R35: 0.44557133 | S35: 0.2470489 | T35: 0.16388616 | U35: 0.019 | V35: NA | W35: NA | X35: NA | Y35: NA | Z35: NA | AA35: NA | AB35: NA | AC35: NA | AD35: NA | AE35: NA | AF35: NA | AG35: NA | AH35: NA | AI35: NA | AJ35: NA | AK35: NA | AL35: NA | AM35: NA | AS35: Sundaram Banking & PSU Fund(G) | AT35: 0.42 | AU35: 45716 | AV35: 337.32435 | AX35: 0.013264 | AY35: 0.022941 | AZ35: 0.038371 | BA35: 0.083365 | BB35: 0.063686 | BC35: 0.057521 | BD35: 0.066899 | BF35: 0.022941 | BG35: 0.07993559 | BH35: 0.068439989 | BI35: 0.029962482 | BJ35: 0.029320025 | BK35: 0.076413426 | BL35: 0.10060673 | BM35: 0.060618277 | BN35: 0.062326518 | BO35: 0.078846837 | BP35: 0.084668925 | BQ35: 0.09353197 | BR35: 0.08514809 | BS35: 0.099285758 | BT35: 0.093251631 | BU35: 0.049139128
B36: Bandhan Core Equity Fund-Reg(G) | C36: 1.73 | D36: 45838 | E36: 9735.3598 | F36: -0.012477 | G36: 0.059945 | H36: 0.079903 | I36: 0.000762 | J36: 0.24794 | K36: 0.266451 | L36: 0.150467 | N36: 0.0204 | O36: 0.28787113 | P36: 0.36235542 | Q36: 0.069317362 | R36: 0.34075077 | S36: 0.12937063 | T36: 0.036936324 | U36: -0.051098343 | V36: 0.3728786 | W36: 0.079863436 | X36: 0.052144719 | Y36: 0.2862369 | Z36: 0.025146496 | AA36: 0.37255676 | AB36: -0.26785151 | AC36: 0.14380919 | AD36: 0.67055037 | AE36: -0.54815031 | AF36: 0.67206247 | AG36: 0.28918114 | AH36: 0.209 | AI36: NA | AJ36: NA | AK36: NA | AL36: NA | AM36: NA | AS36: TRUSTMF Banking & PSU Fund-Reg(G) | AT36: 0.71 | AU36: 45716 | AV36: 219.21459 | AX36: 0.01061 | AY36: 0.021104 | AZ36: 0.035627 | BA36: 0.078579 | BB36: 0.057286 | BC36: NA | BD36: NA | BF36: 0.021104 | BG36: 0.074403405 | BH36: 0.064901266 | BI36: 0.02073183 | BJ36: 0.0407282 | BK36: NA | BL36: NA | BM36: NA | BN36: NA | BO36: NA | BP36: NA | BQ36: NA | BR36: NA | BS36: NA | BT36: NA | BU36: NA
